Workbook

Sheet DATOS Y RESPUESTAS
B2: ESCALA DE ANSIEDAD MANIFIESTA EN ADULTOS
E3: AMAS
B5: Nombre: | C5: E.
B6: Apellidos: | C6: E.
B7: Sexo: | C7: E.
B8: Edad: | C8: E.
B9: Institución: | C9: E.
B10: Evaluador: | C10: E.
B11: Fecha: | C11: E.
B13: FORMA | C13: A | D13: ESCRIBE LA FORMA APLICADA (A, C ó E)
B15: ESCRIBE UNA "X" DEBAJO DE "SI" O "NO" SEGUN LAS RESPUESTAS DEL EXAMINADO
B17: ÍTEM | C17: SI | D17: NO
B18: 1 | C18: X | D18: X
B19: 2 | C19: X | D19: X
B20: 3 | C20: X | D20: X
B21: 4 | C21: X | D21: X
B22: 5 | C22: X | D22: X
B23: 6 | C23: X | D23: X
B24: 7 | C24: X | D24: X
B25: 8 | C25: X | D25: X
B26: 9 | C26: X | D26: X
B27: 10 | C27: X | D27: X
B28: 11 | C28: X | D28: X
B29: 12 | C29: X | D29: X
... B66: 49 | C66: X | D66: X

Sheet RESULTADOS
B2: ESCALA DE ANSIEDAD MANIFIESTA EN ADULTOS
E3: AMAS
B12: Nombre: | C12: ='DATOS Y RESPUESTAS'!C5:H5 -> E.
B13: Apellidos: | C13: ='DATOS Y RESPUESTAS'!C6:H6 -> E.
B14: Sexo: | C14: ='DATOS Y RESPUESTAS'!C7:H7 -> E.
B15: Edad: | C15: ='DATOS Y RESPUESTAS'!C8:H8 -> E.
B16: Institución: | C16: ='DATOS Y RESPUESTAS'!C9:H9 -> E.
B17: Evaluador: | C17: ='DATOS Y RESPUESTAS'!C10:H10 -> E.
B18: Fecha: | C18: ='DATOS Y RESPUESTAS'!C11:H11 -> E.
B20: ÁREAS | F20: PD | G20: PT | H20: Percentil | I20: Categoría
B21: INQUIETUD/HIPERSENSIBILIDAD | F21: =RR!K16 -> 14 | G21: =RR!L16 -> 71 | H21: =RR!M16 -> 99 | I21: =RR!N16 -> CLINICAMENTE SIGNIFICATIVA
B22: ANSIEDAD FISIOLOGICA | F22: =RR!K17 -> 9 | G22: =RR!L17 -> 75 | H22: =RR!M17 -> 99 | I22: =RR!N17 -> EXTREMO
B23: PREOCUPACIONES SOCIALES/ESTRÉS | F23: =RR!K18 -> 7 | G23: =RR!L18 -> 72 | H23: =RR!M18 -> 99 | I23: =RR!N18 -> CLINICAMENTE SIGNIFICATIVA
B25: ANSIEDAD TOTAL | F25: =RR!K20 -> 30 | G25: =RR!L20 -> 77 | H25: =RR!M20 -> 99 | I25: =RR!N20 -> EXTREMO
F27: PD | G27: PT | H27: Percentil | I27: Categoría
B28: MENTIRA | F28: =RR!K23 -> 6 | G28: =RR!L23 -> 65 | H28: =RR!M23 -> 93 | I28: =RR!N23 -> CLINICAMENTE SIGNIFICATIVA
I29: Validéz
I30: =RR!O23 -> CUESTIONABLE
B33: INQUIETUD/HIPERSENSIBILIDAD | C33: =H21 -> 99
B34: ANSIEDAD FISIOLOGICA | C34: =H22 -> 99
B35: PREOCUPACIONES SOCIALES/ESTRÉS | C35: =H23 -> 99

Sheet RR
A5: =IF('DATOS Y RESPUESTAS'!C13="a",1,0) -> 1 | B5: =IF('DATOS Y RESPUESTAS'!C13="c",2,0) -> 0 | C5: =IF('DATOS Y RESPUESTAS'!C13="e",3,0) -> 0 | E5: =SUM(A5:C5) -> 1
B11: 1 | C11: =IF('DATOS Y RESPUESTAS'!C18="x",1,0) -> 1
B12: 2 | C12: =IF('DATOS Y RESPUESTAS'!C19="x",1,0) -> 1
B13: 3 | C13: =IF('DATOS Y RESPUESTAS'!C20="x",1,0) -> 1 | E13: FORMA | F13: A
B14: 4 | C14: =IF('DATOS Y RESPUESTAS'!C21="x",1,0) -> 1
B15: 5 | C15: =IF('DATOS Y RESPUESTAS'!C22="x",1,0) -> 1 | E15: INQUIETUD/HIPERSENSIBILIDAD | I15: ÁREAS | K15: =R15 -> Puntuación Directa | L15: =S15 -> Puntuación T | M15: Percentil | N15: Categoria | R15: Puntuación Directa | S15: Puntuación T | T15: Percentil | U15: Nivel | X15: 1 | Z15: =W15 | AA15: =X15 -> 1
B16: 6 | C16: =IF('DATOS Y RESPUESTAS'!C23="x",1,0) -> 1 | E16: ANSIEDAD FISIOLOGICA | I16: =P16 -> INQUIETUD/HIPERSENSIBILIDAD | K16: =R16 -> 14 | L16: =S16 -> 71 | M16: =T16 -> 99 | N16: =U16 -> CLINICAMENTE SIGNIFICATIVA | P16: =E15 -> INQUIETUD/HIPERSENSIBILIDAD | R16: =LOOKUP(E5,S35:S37,V35:V37) -> 14 | S16: =LOOKUP(E5,S41:S43,V41:V43) -> 71 | T16: =LOOKUP(E5,S45:S47,V45:V47) -> 99 | U16: =LOOKUP(S16,BP19:BQ118) -> CLINICAMENTE SIGNIFICATIVA | W16: =P20 -> ANSIEDAD TOTAL | X16: =T20 -> 99 | Z16: =W16 -> ANSIEDAD TOTAL | AA16: =X16 -> 99 | AI16: A | AS16: C | BE16: E
B17: 7 | C17: =IF('DATOS Y RESPUESTAS'!C24="x",1,0) -> 1 | E17: PREOCUPACIONES SOCIALES/ESTRÉS | I17: =P17 -> ANSIEDAD FISIOLOGICA | K17: =R17 -> 9 | L17: =S17 -> 75 | M17: =T17 -> 99 | N17: =U17 -> EXTREMO | P17: =E16 -> ANSIEDAD FISIOLOGICA | R17: =LOOKUP(E5,S35:S37,W35:W37) -> 9 | S17: =LOOKUP(E5,S41:S43,W41:W43) -> 75 | T17: =LOOKUP(E5,S45:S47,W45:W47) -> 99 | U17: =LOOKUP(S17,BP19:BQ118) -> EXTREMO | W17: =P16 -> INQUIETUD/HIPERSENSIBILIDAD | X17: =T16 -> 99 | Z17: =W17 -> INQUIETUD/HIPERSENSIBILIDAD | AA17: =X17 -> 99 | AI17: INQUIE | AK17: ANSIE | AM17: PREOC/TEMOR | AO17: MENTIRA | AQ17: TTAL | AS17: INQUIE | AU17: ANSIE | AW17: PREOC/TEMOR | AY17: ANSIE EXAM | BA17: MENTIRA | BC17: TTAL | BE17: INQUIE | BG17: ANSIE | BI17: PREOC/TEMOR | BK17: MENTIRA | BM17: TTAL
B18: 8 | C18: =IF('DATOS Y RESPUESTAS'!C25="x",1,0) -> 1 | I18: =P18 -> PREOCUPACIONES SOCIALES/ESTRÉS | K18: =R18 -> 7 | L18: =S18 -> 72 | M18: =T18 -> 99 | N18: =U18 -> CLINICAMENTE SIGNIFICATIVA | P18: =LOOKUP(E5,P29:Q31) -> PREOCUPACIONES SOCIALES/ESTRÉS | R18: =LOOKUP(E5,S35:S37,X35:X37) -> 7 | S18: =LOOKUP(E5,S41:S43,X41:X43) -> 72 | T18: =LOOKUP(E5,S45:S47,X45:X47) -> 99 | U18: =LOOKUP(S18,BP19:BQ118) -> CLINICAMENTE SIGNIFICATIVA | W18: =P17 -> ANSIEDAD FISIOLOGICA | X18: =T17 -> 99 | Z18: =W18 -> ANSIEDAD FISIOLOGICA | AA18: =X18 -> 99 | AI18: 1 | AK18: 2 | AM18: 3 | AO18: 5 | AQ18: 6 | AS18: 1 | AU18: 2 | AW18: 3 | AY18: 4 | BA18: 5 | BC18: 6 | BE18: 1 | BG18: 2 | BI18: 3 | BK18: 5 | BM18: 6
B19: 9 | C19: =IF('DATOS Y RESPUESTAS'!C26="x",1,0) -> 1 | E19: MENTIRA | I19: =P19 -> - | K19: =R19 -> - | L19: =S19 -> - | M19: =T19 -> - | N19: =U19 -> - | P19: =LOOKUP(E5,P29:P31,R29:R31) -> - | R19: =LOOKUP(E5,S35:S37,Y35:Y37) -> - | S19: =LOOKUP(E5,S41:S43,Y41:Y43) -> - | T19: =LOOKUP(E5,S45:S47,Y45:Y47) -> - | U19: =IF(E5=2,LOOKUP(S19,BP19:BQ118),"-") -> - | W19: =P18 -> PREOCUPACIONES SOCIALES/ESTRÉS | X19: =T18 -> 99 | Z19: =W19 -> PREOCUPACIONES SOCIALES/ESTRÉS | AA19: =X19 -> 99 | AH19: 0 | AI19: 30 | AJ19: 1 | AK19: 39 | AL19: 11 | AM19: 34 | AN19: 4 | AO19: 35 | AP19: 8 | AQ19: 31 | AR19: 0 | AS19: 28 | AT19: 1 | AU19: 39 | AV19: 12 | AW19: 40 | AX19: 16 | AY19: 37 | AZ19: 5 | BA19: 35 | BB19: 7 | BC19: 32 | BD19: 0 | BE19: 31 | BF19: 0 | BG19: 31 | BH19: 3 | BI19: 25 | BJ19: 2 | BK19: 31 | BL19: 4 | BM19: 27 | BN19: 1 | BP19: 1 | BQ19: BAJO | BR19: CUESTIONABLE
B20: 10 | C20: =IF('DATOS Y RESPUESTAS'!C27="x",1,0) -> 1 | E20: ANSIEDAD TOTAL | I20: =P20 -> ANSIEDAD TOTAL | K20: =R20 -> 30 | L20: =S20 -> 77 | M20: =T20 -> 99 | N20: =U20 -> EXTREMO | P20: ANSIEDAD TOTAL | R20: =LOOKUP(E5,S35:S37,AA35:AA37) -> 30 | S20: =LOOKUP(E5,S41:S43,AA41:AA43) -> 77 | T20: =LOOKUP(E5,S45:S47,AA45:AA47) -> 99 | U20: =LOOKUP(S20,BP19:BQ118) -> EXTREMO | W20: =P19 -> - | X20: =S19 -> - | AA20: 99 | AH20: 1 | AI20: 33 | AJ20: 4 | AK20: 43 | AL20: 30 | AM20: 40 | AN20: 16 | AO20: 40 | AP20: 22 | AQ20: 33 | AR20: 1 | AS20: 32 | AT20: 4 | AU20: 44 | AV20: 34 | AW20: 46 | AX20: 44 | AY20: 40 | AZ20: 15 | BA20: 40 | BB20: 20 | BC20: 33 | BD20: 1 | BE20: 32 | BF20: 2 | BG20: 36 | BH20: 11 | BI20: 30 | BJ20: 5 | BK20: 36 | BL20: 13 | BM20: 28 | BN20: 1 | BP20: 2 | BQ20: BAJO | BR20: CUESTIONABLE
B21: 11 | C21: =IF('DATOS Y RESPUESTAS'!C28="x",1,0) -> 1 | X21: 99 | AH21: 2 | AI21: 36 | AJ21: 8 | AK21: 47 | AL21: 45 | AM21: 45 | AN21: 36 | AO21: 45 | AP21: 35 | AQ21: 34 | AR21: 3 | AS21: 36 | AT21: 8 | AU21: 48 | AV21: 52 | AW21: 52 | AX21: 65 | AY21: 42 | AZ21: 27 | BA21: 44 | BB21: 34 | BC21: 34 | BD21: 2 | BE21: 34 | BF21: 4 | BG21: 42 | BH21: 23 | BI21: 35 | BJ21: 11 | BK21: 40 | BL21: 21 | BM21: 30 | BN21: 1 | BP21: 3 | BQ21: BAJO | BR21: CUESTIONABLE
B22: 12 | C22: =IF('DATOS Y RESPUESTAS'!C29="x",1,0) -> 1 | E22: FORMA | F22: C | K22: =R22 -> Puntuación Directa | L22: =S22 -> Puntuación T | M22: Percentil | N22: Categoria | O22: Evaluación de validez | R22: Puntuación Directa | S22: Puntuación T | T22: Percentil | U22: Nivel | V22: Evaluación de validez | AH22: 3 | AI22: 39 | AJ22: 15 | AK22: 51 | AL22: 58 | AM22: 51 | AN22: 57 | AO22: 50 | AP22: 49 | AQ22: 36 | AR22: 6 | AS22: 39 | AT22: 16 | AU22: 53 | AV22: 67 | AW22: 58 | AX22: 79 | AY22: 45 | AZ22: 38 | BA22: 49 | BB22: 49 | BC22: 35 | BD22: 4 | BE22: 36 | BF22: 8 | BG22: 47 | BH22: 37 | BI22: 40 | BJ22: 19 | BK22: 45 | BL22: 30 | BM22: 31 | BN22: 2 | BP22: 4 | BQ22: BAJO | BR22: CUESTIONABLE
B23: 13 | C23: =IF('DATOS Y RESPUESTAS'!C30="x",1,0) -> 1 | I23: =P23 -> MENTIRA | K23: =R23 -> 6 | L23: =S23 -> 65 | M23: =T23 -> 93 | N23: =U23 -> CLINICAMENTE SIGNIFICATIVA | O23: =V23 -> CUESTIONABLE | P23: MENTIRA | R23: =LOOKUP(E5,S35:S37,Z35:Z37) -> 6 | S23: =LOOKUP(E5,S41:S43,Z41:Z43) -> 65 | T23: =LOOKUP(E5,S45:S47,Z45:Z47) -> 93 | U23: =LOOKUP(S23,BP19:BQ118) -> CLINICAMENTE SIGNIFICATIVA | V23: =LOOKUP(S23,BP19:BP118,BR19:BR118) -> CUESTIONABLE | AH23: 4 | AI23: 42 | AJ23: 23 | AK23: 55 | AL23: 70 | AM23: 56 | AN23: 74 | AO23: 55 | AP23: 63 | AQ23: 37 | AR23: 10 | AS23: 43 | AT23: 27 | AU23: 58 | AV23: 78 | AW23: 64 | AX23: 88 | AY23: 48 | AZ23: 49 | BA23: 54 | BB23: 61 | BC23: 37 | BD23: 6 | BE23: 37 | BF23: 12 | BG23: 52 | BH23: 56 | BI23: 45 | BJ23: 29 | BK23: 49 | BL23: 43 | BM23: 32 | BN23: 3 | BP23: 5 | BQ23: BAJO | BR23: CUESTIONABLE
B24: 14 | C24: =IF('DATOS Y RESPUESTAS'!C31="x",1,0) -> 1 | E24: INQUIETUD/HIPERSENSIBILIDAD | AH24: 5 | AI24: 45 | AJ24: 34 | AK24: 59 | AL24: 79 | AM24: 61 | AN24: 86 | AO24: 60 | AP24: 78 | AQ24: 39 | AR24: 14 | AS24: 46 | AT24: 37 | AU24: 62 | AV24: 85 | AW24: 69 | AX24: 94 | AY24: 51 | AZ24: 59 | BA24: 59 | BB24: 77 | BC24: 38 | BD24: 10 | BE24: 39 | BF24: 17 | BG24: 57 | BH24: 73 | BI24: 51 | BJ24: 43 | BK24: 54 | BL24: 56 | BM24: 33 | BN24: 5 | BP24: 6 | BQ24: BAJO | BR24: CUESTIONABLE
B25: 15 | C25: =IF('DATOS Y RESPUESTAS'!C32="x",1,0) -> 1 | E25: ANSIEDAD FISIOLOGICA | AH25: 6 | AI25: 48 | AJ25: 45 | AK25: 63 | AL25: 86 | AM25: 67 | AN25: 95 | AO25: 65 | AP25: 93 | AQ25: 40 | AR25: 18 | AS25: 50 | AT25: 47 | AU25: 67 | AV25: 91 | AW25: 75 | AX25: 97 | AY25: 53 | AZ25: 66 | BA25: 63 | BB25: 91 | BC25: 39 | BD25: 13 | BE25: 41 | BF25: 22 | BG25: 62 | BH25: 87 | BI25: 56 | BJ25: 64 | BK25: 58 | BL25: 74 | BM25: 34 | BN25: 7 | BP25: 7 | BQ25: BAJO | BR25: CUESTIONABLE
B26: 16 | C26: =IF('DATOS Y RESPUESTAS'!C33="x",1,0) -> 1 | E26: PREOCUPACIONES SOCIALES/ESTRÉS | AH26: 7 | AI26: 51 | AJ26: 56 | AK26: 67 | AL26: 92 | AM26: 72 | AN26: 99 | AQ26: 42 | AR26: 24 | AS26: 53 | AT26: 59 | AU26: 71 | AV26: 97 | AW26: 81 | AX26: 99 | AY26: 56 | AZ26: 73 | BA26: 68 | BB26: 98 | BC26: 40 | BD26: 17 | BE26: 42 | BF26: 27 | BG26: 68 | BH26: 97 | BI26: 61 | BJ26: 87 | BK26: 63 | BL26: 93 | BM26: 35 | BN26: 9 | BP26: 8 | BQ26: BAJO | BR26: CUESTIONABLE
B27: 17 | C27: =IF('DATOS Y RESPUESTAS'!C34="x",1,0) -> 1 | E27: ANSIEDAD ANTE LOS EXÁMENES | AH27: 8 | AI27: 54 | AJ27: 65 | AK27: 71 | AL27: 97 | AQ27: 43 | AR27: 29 | AS27: 57 | AT27: 72 | AU27: 76 | AV27: 99 | AY27: 59 | AZ27: 80 | BC27: 41 | BD27: 21 | BE27: 44 | BF27: 32 | BM27: 36 | BN27: 11 | BP27: 9 | BQ27: BAJO | BR27: CUESTIONABLE
B28: 18 | C28: =IF('DATOS Y RESPUESTAS'!C35="x",1,0) -> 1 | E28: MENTIRA | Q28: 3 | R28: 4 | S28: 5 | U28: 6 | AH28: 9 | AI28: 57 | AJ28: 47 | AK28: 75 | AL28: 99 | AQ28: 45 | AR28: 33 | AS28: 60 | AT28: 83 | AY28: 62 | AZ28: 85 | BC28: 43 | BD28: 26 | BE28: 46 | BF28: 37 | BM28: 37 | BN28: 13 | BP28: 10 | BQ28: BAJO | BR28: CUESTIONABLE
B29: 19 | C29: =IF('DATOS Y RESPUESTAS'!C36="x",1,0) -> 1 | E29: ANSIEDAD TOTAL | P29: 1 | Q29: PREOCUPACIONES SOCIALES/ESTRÉS | R29: - | AH29: 10 | AI29: 60 | AJ29: 81 | AQ29: 46 | AR29: 39 | AS29: 64 | AT29: 92 | AY29: 65 | AZ29: 89 | BC29: 44 | BD29: 31 | BE29: 47 | BF29: 43 | BM29: 39 | BN29: 15 | BP29: 11 | BQ29: BAJO | BR29: CUESTIONABLE
B30: 20 | C30: =IF('DATOS Y RESPUESTAS'!C37="x",1,0) -> 1 | P30: 2 | Q30: PREOCUPACIONES SOCIALES/ESTRÉS | R30: ANSIEDAD ANTE LOS EXÁMENES | AH30: 11 | AI30: 62 | AJ30: 86 | AQ30: 48 | AR30: 46 | AS30: 67 | AT30: 97 | AY30: 67 | AZ30: 93 | BC30: 45 | BD30: 36 | BE30: 49 | BF30: 48 | BM30: 40 | BN30: 18 | BP30: 12 | BQ30: BAJO | BR30: CUESTIONABLE
B31: 21 | C31: =IF('DATOS Y RESPUESTAS'!C38="x",1,0) -> 1 | E31: FORMA | F31: E | P31: 3 | Q31: TEMOR AL ENVEJECIMIENTO | R31: - | AH31: 12 | AI31: 65 | AJ31: 92 | AQ31: 49 | AR31: 53 | AS31: 71 | AT31: 99 | AY31: 70 | AZ31: 96 | BC31: 46 | BD31: 41 | BE31: 51 | BF31: 53 | BM31: 41 | BN31: 20 | BP31: 13 | BQ31: BAJO | BR31: CUESTIONABLE
B32: 22 | C32: =IF('DATOS Y RESPUESTAS'!C39="x",1,0) -> 1 | AH32: 13 | AI32: 68 | AJ32: 96 | AQ32: 51 | AR32: 60 | AY32: 73 | AZ32: 98 | BC32: 48 | BD32: 45 | BE32: 52 | BF32: 57 | BM32: 42 | BN32: 23 | BP32: 14 | BQ32: BAJO | BR32: CUESTIONABLE
B33: 23 | C33: =IF('DATOS Y RESPUESTAS'!C40="x",1,0) -> 1 | E33: INQUIETUD/HIPERSENSIBILIDAD | V33: INQUIE | W33: ANSIE | X33: PREOC/TEMOR | Y33: ANSIE | Z33: MENTIRA | AA33: TTAL | AH33: 14 | AI33: 71 | AJ33: 99 | AQ33: 52 | AR33: 64 | AY33: 76 | AZ33: 99 | BC33: 49 | BD33: 50 | BE33: 54 | BF33: 61 | BM33: 43 | BN33: 26 | BP33: 15 | BQ33: BAJO | BR33: CUESTIONABLE
B34: 24 | C34: =IF('DATOS Y RESPUESTAS'!C41="x",1,0) -> 1 | E34: ANSIEDAD FISIOLOGICA | V34: 1 | W34: 2 | X34: 3 | Y34: 4 | Z34: 5 | AA34: 6 | AH34: 15 | AQ34: 54 | AR34: 69 | AY34: 79 | AZ34: 99 | BC34: 50 | BD34: 55 | BE34: 56 | BF34: 67 | BM34: 44 | BN34: 30 | BP34: 16 | BQ34: BAJO | BR34: CUESTIONABLE
B35: 25 | C35: =IF('DATOS Y RESPUESTAS'!C42="x",1,0) -> 1 | E35: TEMOR AL ENVEJECIMIENTO | S35: 1 | U35: A | V35: =SUM(C11+C15+C17+C19+C23+C26+C28+C30+C32+C35+C39+C41+C43+C46) -> 14 | W35: =SUM(C12+C16+C20+C24+C27+C31+C36+C40+C44) -> 9 | X35: =SUM(C13+C21+C25+C29+C33+C37+C45) -> 7 | Y35: - | Z35: =SUM(C14+C18+C22+C34+C38+C42) -> 6 | AA35: =SUM(V35+W35+X35) -> 30 | AH35: 16 | AQ35: 55 | AR35: 73 | BC35: 51 | BD35: 60 | BE35: 57 | BF35: 72 | BM35: 45 | BN35: 34 | BP35: 17 | BQ35: BAJO | BR35: CUESTIONABLE
B36: 26 | C36: =IF('DATOS Y RESPUESTAS'!C43="x",1,0) -> 1 | S36: 2 | U36: C | V36: =SUM(C14+C16+C23+C25+C28+C32+C35+C39+C45+C53+C56+C59) -> 12 | W36: =SUM(C29+C40+C42+C44+C46+C50+C55+C57) -> 8 | X36: =SUM(C11+C13+C19+C22+C36+C48+C52) -> 7 | Y36: =SUM(C12+C15+C17+C21+C24+C27+C30+C33+C37+C41+C43+C47+C49+C51+C54) -> 15 | Z36: =SUM(C18+C20+C26+C31+C34+C38+C58) -> 7 | AA36: =SUM(V36+W36+X36+Y36) -> 42 | AH36: 17 | AQ36: 57 | AR36: 75 | BC36: 53 | BD36: 65 | BE36: 59 | BF36: 78 | BM36: 46 | BN36: 38 | BP36: 18 | BQ36: BAJO | BR36: CUESTIONABLE
B37: 27 | C37: =IF('DATOS Y RESPUESTAS'!C44="x",1,0) -> 1 | E37: MENTIRA | S37: 3 | U37: E | V37: =SUM(C15+C16+C18+C20+C21+C23+C25+C27+C29+C31+C32+C34+C36+C37+C39+C40+C44+C45+C46+C48+C49+C52+C54) -> 23 | W37: =SUM(C11+C13+C14+C28+C30+C33+C47) -> 7 | X37: =SUM(C19+C35+C38+C41+C43+C50+C51) -> 7 | Y37: - | Z37: =SUM(C12+C17+C22+C24+C26+C42+C53) -> 7 | AA37: =SUM(V37+W37+X37) -> 37 | AH37: 18 | AQ37: 58 | AR37: 78 | BC37: 54 | BD37: 70 | BE37: 60 | BF37: 82 | BM37: 48 | BN37: 41 | BP37: 19 | BQ37: BAJO | BR37: CUESTIONABLE
B38: 28 | C38: =IF('DATOS Y RESPUESTAS'!C45="x",1,0) -> 1 | E38: ANSIEDAD TOTAL | AH38: 19 | AQ38: 60 | AR38: 81 | BC38: 55 | BD38: 73 | BE38: 62 | BF38: 86 | BM38: 49 | BN38: 45 | BP38: 20 | BQ38: BAJO | BR38: CUESTIONABLE
B39: 29 | C39: =IF('DATOS Y RESPUESTAS'!C46="x",1,0) -> 1 | AH39: 20 | AQ39: 61 | AR39: 84 | BC39: 56 | BD39: 76 | BE39: 64 | BF39: 89 | BM39: 50 | BN39: 49 | BP39: 21 | BQ39: BAJO | BR39: CUESTIONABLE
B40: 30 | C40: =IF('DATOS Y RESPUESTAS'!C47="x",1,0) -> 1 | V40: 1 | W40: 2 | X40: 3 | Y40: 4 | Z40: 5 | AA40: 6 | AH40: 21 | AQ40: 63 | AR40: 87 | BC40: 58 | BD40: 79 | BE40: 65 | BF40: 93 | BM40: 51 | BN40: 53 | BP40: 22 | BQ40: BAJO | BR40: CUESTIONABLE
B41: 31 | C41: =IF('DATOS Y RESPUESTAS'!C48="x",1,0) -> 1 | S41: 1 | U41: A | V41: =LOOKUP(V35,RR!AH19:AH33,RR!AI19:AI33) -> 71 | W41: =LOOKUP(W35,RR!AH19:AH28,RR!AK19:AK28) -> 75 | X41: =LOOKUP(X35,RR!AH19:AH26,RR!AM19:AM26) -> 72 | Y41: - | Z41: =LOOKUP(Z35,RR!AH19:AH25,RR!AO19:AO25) -> 65 | AA41: =LOOKUP(AA35,RR!AH19:AH49,RR!AQ19:AQ49) -> 77 | AH41: 22 | AQ41: 64 | AR41: 90 | BC41: 59 | BD41: 81 | BE41: 67 | BF41: 96 | BM41: 52 | BN41: 56 | BP41: 23 | BQ41: BAJO | BR41: CUESTIONABLE
B42: 32 | C42: =IF('DATOS Y RESPUESTAS'!C49="x",1,0) -> 1 | S42: 2 | U42: C | V42: =LOOKUP(V36,RR!AH19:AH31,RR!AS19:AS31) -> 71 | W42: =LOOKUP(W36,RR!AH19:AH27,RR!AU19:AU27) -> 76 | X42: =LOOKUP(X35,RR!AH19:AH26,RR!AW19:AW26) -> 81 | Y42: =LOOKUP(Y36,RR!AH19:AH34,RR!AY19:AY34) -> 79 | Z42: =LOOKUP(Z36,RR!AH19:AH26,RR!BA19:BA26) -> 68 | AA42: =LOOKUP(AA36,RR!AH19:AH61,RR!BC19:BC61) -> 84 | AH42: 23 | AQ42: 66 | AR42: 92 | BC42: 60 | BD42: 83 | BE42: 69 | BF42: 99 | BM42: 53 | BN42: 60 | BP42: 24 | BQ42: BAJO | BR42: CUESTIONABLE
B43: 33 | C43: =IF('DATOS Y RESPUESTAS'!C50="x",1,0) -> 1 | S43: 3 | U43: E | V43: =LOOKUP(V37,RR!AH19:AH42,RR!BE19:BE42) -> 69 | W43: =LOOKUP(W37,RR!AH19:AH26,RR!BG19:BG26) -> 68 | X43: =LOOKUP(,RR!AH19:AH26,RR!BI19:BI26) -> 25 | Y43: - | Z43: =LOOKUP(Z37,RR!AH19:AH26,RR!BK19:BK26) -> 63 | AA43: =LOOKUP(AA37,RR!AH19:AH56,RR!BM19:BM56) -> 69 | AH43: 24 | AQ43: 68 | AR43: 94 | BC43: 61 | BD43: 86 | BM43: 54 | BN43: 63 | BP43: 25 | BQ43: BAJO | BR43: CUESTIONABLE
B44: 34 | C44: =IF('DATOS Y RESPUESTAS'!C51="x",1,0) -> 1 | AH44: 25 | AQ44: 70 | AR44: 96 | BC44: 63 | BD44: 88 | BM44: 55 | BN44: 66 | BP44: 26 | BQ44: BAJO | BR44: CUESTIONABLE
B45: 35 | C45: =IF('DATOS Y RESPUESTAS'!C52="x",1,0) -> 1 | S45: 1 | U45: A | V45: =LOOKUP(V35,AH19:AH33,AJ19:AJ33) -> 99 | W45: =LOOKUP(W35,AH19:AH28,AL19:AL28) -> 99 | X45: =LOOKUP(X35,AH19:AH26,AN19:AN26) -> 99 | Y45: - | Z45: =LOOKUP(Z35,AH19:AH25,AP19:AP25) -> 93 | AA45: =LOOKUP(AA35,AH19:AH49,AR19:AR49) -> 99 | AH45: 26 | AQ45: 71 | AR45: 97 | BC45: 64 | BD45: 89 | BM45: 57 | BN45: 70 | BP45: 27 | BQ45: BAJO | BR45: CUESTIONABLE
B46: 36 | C46: =IF('DATOS Y RESPUESTAS'!C53="x",1,0) -> 1 | S46: 2 | U46: C | V46: =LOOKUP(V36,AH19:AH31,AT19:AT31) -> 99 | W46: =LOOKUP(W36,AH19:AH27,AV19:AV27) -> 99 | X46: =LOOKUP(X36,AH19:AH26,AX19:AX26) -> 99 | Y46: =LOOKUP(Y36,AH19:AH34,AZ19:AZ34) -> 99 | Z46: =LOOKUP(Z36,AH19:AH26,BB19:BB26) -> 98 | AA46: =LOOKUP(AA36,AH19:AH61,BD19:BD61) -> 99 | AH46: 27 | AQ46: 72 | AR46: 98 | BC46: 65 | BD46: 91 | BM46: 58 | BN46: 74 | BP46: 28 | BQ46: BAJO | BR46: CUESTIONABLE
B47: 37 | C47: =IF('DATOS Y RESPUESTAS'!C54="x",1,0) -> 1 | S47: 3 | U47: E | V47: =LOOKUP(V37,AH19:AH42,BF19:BF42) -> 99 | W47: =LOOKUP(W37,AH19:AH26,BG19:BG26) -> 68 | X47: =LOOKUP(X37,AH19:AH26,BI19:BI26) -> 61 | Y47: - | Z47: =LOOKUP(Z37,AH19:AH26,BL19:BL26) -> 93 | AA47: =LOOKUP(AA37,AH19:AH56,BN19:BN56) -> 99 | AH47: 28 | AQ47: 74 | AR47: 99 | BC47: 66 | BD47: 93 | BM47: 59 | BN47: 78 | BP47: 29 | BQ47: BAJO | BR47: CUESTIONABLE
B48: 38 | C48: =IF('DATOS Y RESPUESTAS'!C55="x",1,0) -> 1 | AH48: 29 | AQ48: 75 | AR48: 99 | BC48: 68 | BD48: 94 | BM48: 60 | BN48: 81 | BP48: 30 | BQ48: BAJO | BR48: CUESTIONABLE
B49: 39 | C49: =IF('DATOS Y RESPUESTAS'!C56="x",1,0) -> 1 | AH49: 30 | AQ49: 77 | AR49: 99 | BC49: 69 | BD49: 95 | BM49: 61 | BN49: 84 | BP49: 31 | BQ49: BAJO | BR49: CUESTIONABLE
...

Sheet REPORTE
C2: ESCALA DE ANSIEDAD MANIFIESTA EN ADULTOS
A4: ='DATOS Y RESPUESTAS'!B5 -> Nombre: | B4: ='DATOS Y RESPUESTAS'!C5 -> E.
A5: ='DATOS Y RESPUESTAS'!B6 -> Apellidos: | B5: ='DATOS Y RESPUESTAS'!C6 -> E.
A6: ='DATOS Y RESPUESTAS'!B7 -> Sexo: | B6: ='DATOS Y RESPUESTAS'!C7 -> E.
A7: ='DATOS Y RESPUESTAS'!B8 -> Edad: | B7: ='DATOS Y RESPUESTAS'!C8 -> E.
A8: ='DATOS Y RESPUESTAS'!B9 -> Institución: | B8: ='DATOS Y RESPUESTAS'!C9 -> E.
A9: ='DATOS Y RESPUESTAS'!B10 -> Evaluador: | B9: ='DATOS Y RESPUESTAS'!C10 -> E.
A10: ='DATOS Y RESPUESTAS'!B11 -> Fecha: | B10: ='DATOS Y RESPUESTAS'!C11 -> E.
A12: ='DATOS Y RESPUESTAS'!B13 -> FORMA | B12: ='DATOS Y RESPUESTAS'!C13 -> A
C14: =RR!I15 -> ÁREAS | D14: PD | E14: PT | F14: PC | G14: =RR!N15 -> Categoria
C15: =RR!I16 -> INQUIETUD/HIPERSENSIBILIDAD | D15: =RR!K16 -> 14 | E15: =RR!L16 -> 71 | F15: =RR!M16 -> 99 | G15: =RR!N16 -> CLINICAMENTE SIGNIFICATIVA
C16: =RR!I17 -> ANSIEDAD FISIOLOGICA | D16: =RR!K17 -> 9 | E16: =RR!L17 -> 75 | F16: =RR!M17 -> 99 | G16: =RR!N17 -> EXTREMO
C17: =RR!I18 -> PREOCUPACIONES SOCIALES/ESTRÉS | D17: =RR!K18 -> 7 | E17: =RR!L18 -> 72 | F17: =RR!M18 -> 99 | G17: =RR!N18 -> CLINICAMENTE SIGNIFICATIVA
C18: =RR!I19 -> - | D18: =RR!K19 -> - | E18: =RR!L19 -> - | F18: =RR!M19 -> - | G18: =RR!N19 -> -
C19: =RR!I20 -> ANSIEDAD TOTAL | D19: =RR!K20 -> 30 | E19: =RR!L20 -> 77 | F19: =RR!M20 -> 99 | G19: =RR!N20 -> EXTREMO
D21: PD | E21: PT | F21: PC | G21: =RR!N22 -> Categoria | H21: =RR!O22 -> Evaluación de validez
C22: =RR!I23 -> MENTIRA | D22: =RR!K23 -> 6 | E22: =RR!L23 -> 65 | F22: =RR!M23 -> 93 | G22: =RR!N23 -> CLINICAMENTE SIGNIFICATIVA | H22: =RR!O23 -> CUESTIONABLE
